Workbook
Name Slicer_Category: #N/A
Name Slicer_Inventory_Status: #N/A
Name Slicer_Region: #N/A
Name Slicer_Supplier: #N/A

Sheet Raw_Data
A1: Order ID | B1: Order Date | C1: Product | D1: Category | E1: Supplier | F1: Warehouse | G1: Region | H1: Opening Stock | I1: Units Received | J1: Units Sold | K1: Closing Stock | L1: Reorder Level | M1: Unit Cost | N1: Lead Time Days | O1: Stockout Days | P1: Supplier Delivery Status | Q1: Inventory Status | R1: Order Status | S1: Inventory Value
A2: ORD00001 | B2: 46070 | C2: Bluetooth Speaker | D2: Electronics | E2: UrbanSupply | F2: Mumbai | G2: West | H2: 97 | I2: 37 | J2: 109 | K2: 25 | L2: 51 | M2: 1863.61 | N2: 6 | O2: 7 | P2: Late | Q2: Low Stock | R2: Delivered | S2: =K2*M2 -> 46590.25
A3: ORD00002 | B3: 46026 | C3: Hoodie | D3: Fashion | E3: DirectWholesale | F3: Bangalore | G3: South | H3: 183 | I3: 45 | J3: 106 | K3: 122 | L3: 86 | M3: 1352.34 | N3: 5 | O3: 0 | P3: On Time | Q3: Healthy | R3: Delivered | S3: =K3*M3 -> 164985.48
A4: ORD00003 | B4: 46158 | C4: Sneakers | D4: Fashion | E4: UrbanSupply | F4: Delhi | G4: North | H4: 79 | I4: 47 | J4: 58 | K4: 68 | L4: 51 | M4: 2204.52 | N4: 2 | O4: 0 | P4: On Time | Q4: Healthy | R4: Delivered | S4: =K4*M4 -> 149907.36
A5: ORD00004 | B5: 46121 | C5: Wireless Mouse | D5: Electronics | E5: DirectWholesale | F5: Bangalore | G5: South | H5: 136 | I5: 30 | J5: 85 | K5: 81 | L5: 63 | M5: 959.29 | N5: 6 | O5: 0 | P5: On Time | Q5: Healthy | R5: Delivered | S5: =K5*M5 -> 77702.49
A6: ORD00005 | B6: 46106 | C6: Bluetooth Speaker | D6: Electronics | E6: PrimeGoods | F6: Delhi | G6: North | H6: 60 | I6: 129 | J6: 44 | K6: 145 | L6: 100 | M6: 1656.36 | N6: 4 | O6: 0 | P6: On Time | Q6: Healthy | R6: Cancelled | S6: =K6*M6 -> 240172.2
A7: ORD00006 | B7: 46259 | C7: Storage Box | D7: Home | E7: PrimeGoods | F7: Delhi | G7: North | H7: 219 | I7: 107 | J7: 97 | K7: 229 | L7: 49 | M7: 817.46 | N7: 3 | O7: 0 | P7: On Time | Q7: Overstock | R7: Delivered | S7: =K7*M7 -> 187198.34
A8: ORD00007 | B8: 46131 | C8: Football | D8: Sports | E8: DirectWholesale | F8: Mumbai | G8: West | H8: 215 | I8: 61 | J8: 22 | K8: 254 | L8: 59 | M8: 1383.67 | N8: 8 | O8: 0 | P8: On Time | Q8: Overstock | R8: Delivered | S8: =K8*M8 -> 351452.18
A9: ORD00008 | B9: 46322 | C9: Sunscreen | D9: Beauty | E9: PrimeGoods | F9: Kolkata | G9: East | H9: 141 | I9: 102 | J9: 73 | K9: 170 | L9: 54 | M9: 619.43 | N9: 3 | O9: 0 | P9: On Time | Q9: Overstock | R9: Delivered | S9: =K9*M9 -> 105303.1
A10: ORD00009 | B10: 46371 | C10: Yoga Mat | D10: Sports | E10: UrbanSupply | F10: Mumbai | G10: West | H10: 75 | I10: 85 | J10: 78 | K10: 82 | L10: 50 | M10: 1051.16 | N10: 8 | O10: 0 | P10: Late | Q10: Healthy | R10: Delivered | S10: =K10*M10 -> 86195.12
A11: ORD00010 | B11: 46081 | C11: Running Shoes | D11: Sports | E11: GlobalMart | F11: Kolkata | G11: East | H11: 192 | I11: 79 | J11: 82 | K11: 189 | L11: 61 | M11: 3063.8 | N11: 8 | O11: 0 | P11: On Time | Q11: Overstock | R11: Pending | S11: =K11*M11 -> 579058.2
A12: ORD00011 | B12: 46279 | C12: Sunscreen | D12: Beauty | E12: UrbanSupply | F12: Bangalore | G12: South | H12: 115 | I12: 75 | J12: 35 | K12: 155 | L12: 74 | M12: 585.42 | N12: 7 | O12: 0 | P12: On Time | Q12: Healthy | R12: Delivered | S12: =K12*M12 -> 90740.1
A13: ORD00012 | B13: 46273 | C13: T-Shirt | D13: Fashion | E13: UrbanSupply | F13: Mumbai | G13: West | H13: 79 | I13: 67 | J13: 35 | K13: 111 | L13: 79 | M13: 763.49 | N13: 6 | O13: 0 | P13: On Time | Q13: Healthy | R13: Delivered | S13: =K13*M13 -> 84747.39
... A1501: ORD01500 | B1501: 46170 | C1501: Coffee Maker | D1501: Home | E1501: GlobalMart | F1501: Bangalore | G1501: South | H1501: 90 | I1501: 85 | J1501: 20 | K1501: 155 | L1501: 71 | M1501: 3169.9 | N1501: 5 | O1501: 1 | P1501: Late | Q1501: Healthy | R1501: Returned | S1501: =K1501*M1501 -> 491334.5

Sheet Analysis
A3: Row Labels | B3: Count of Order ID | C3: Sum of Closing Stock | F3: Count of Order ID | G3: Column Labels | L3: Count of Order ID | M3: Column Labels
A4: Healthy | B4: 768 | C4: 87436 | F4: Row Labels | G4: Late | H4: On Time | I4: Grand Total | J4: Late Delivery Rate | L4: Row Labels | M4: Healthy | N4: Low Stock | O4: Overstock | P4: Grand Total
A5: Low Stock | B5: 128 | C5: 3365 | F5: DirectWholesale | G5: 43 | H5: 232 | I5: 275 | J5: =GETPIVOTDATA("Order ID",$F$3,"Supplier","DirectWholesale","Supplier Delivery Status","Late")/GETPIVOTDATA("Order ID",$F$3,"Supplier","DirectWholesale") -> 0.15636364 | L5: North | M5: 197 | N5: 42 | O5: 151 | P5: 390
A6: Overstock | B6: 604 | C6: 121094 | F6: GlobalMart | G6: 64 | H6: 269 | I6: 333 | J6: =GETPIVOTDATA("Order ID",$F$3,"Supplier","GlobalMart","Supplier Delivery Status","Late")/GETPIVOTDATA("Order ID",$F$3,"Supplier","GlobalMart") -> 0.19219219 | L6: South | M6: 195 | N6: 25 | O6: 154 | P6: 374
A7: Grand Total | B7: 1500 | C7: 211895 | F7: PrimeGoods | G7: 56 | H7: 255 | I7: 311 | J7: =GETPIVOTDATA("Order ID",$F$3,"Supplier","PrimeGoods","Supplier Delivery Status","Late")/GETPIVOTDATA("Order ID",$F$3,"Supplier","PrimeGoods") -> 0.18006431 | L7: West | M7: 200 | N7: 35 | O7: 136 | P7: 371
F8: TechSource | G8: 55 | H8: 228 | I8: 283 | J8: =GETPIVOTDATA("Order ID",$F$3,"Supplier","DirectWholesale","Supplier Delivery Status","Late")/GETPIVOTDATA("Order ID",$F$3,"Supplier","DirectWholesale") -> 0.15636364 | L8: East | M8: 176 | N8: 26 | O8: 163 | P8: 365
A9: Healty % | B9: =GETPIVOTDATA("Count of Order ID",$A$3,"Inventory Status","Healthy")/GETPIVOTDATA("Count of Order ID",$A$3) -> 0.512 | F9: UrbanSupply | G9: 55 | H9: 243 | I9: 298 | J9: =GETPIVOTDATA("Order ID",$F$3,"Supplier","GlobalMart","Supplier Delivery Status","Late")/GETPIVOTDATA("Order ID",$F$3,"Supplier","GlobalMart") -> 0.19219219 | L9: Grand Total | M9: 768 | N9: 128 | O9: 604 | P9: 1500
A10: Low % | B10: =GETPIVOTDATA("Count of Order ID",$A$3,"Inventory Status","Low Stock")/GETPIVOTDATA("Count of Order ID",$A$3) -> 0.085333333 | F10: Grand Total | G10: 273 | H10: 1227 | I10: 1500
A11: Overstock % | B11: =GETPIVOTDATA("Count of Order ID",$A$3,"Inventory Status","Overstock")/GETPIVOTDATA("Count of Order ID",$A$3) -> 0.40266667 | L11: Region | M11: Low Stock % | N11: Overstock %
L12: North | M12: =GETPIVOTDATA("Order ID",$L$3,"Region","North","Inventory Status","Low Stock")/GETPIVOTDATA("Order ID",$L$3,"Region","North") -> 0.10769231 | N12: =GETPIVOTDATA("Order ID",$L$3,"Region","North","Inventory Status","Overstock")/GETPIVOTDATA("Order ID",$L$3,"Region","North") -> 0.38717949
A13: Row Labels | B13: Sum of Inventory Value | F13: Count of Order ID | G13: Column Labels | L13: South | M13: =GETPIVOTDATA("Order ID",$L$3,"Region","South","Inventory Status","Low Stock")/GETPIVOTDATA("Order ID",$L$3,"Region","South") -> 0.06684492 | N13: =GETPIVOTDATA("Order ID",$L$3,"Region","South","Inventory Status","Overstock")/GETPIVOTDATA("Order ID",$L$3,"Region","South") -> 0.41176471
A14: Healthy | B14: 1.2206923e+08 | F14: Row Labels | G14: Late | H14: On Time | I14: Grand Total | L14: West | M14: =GETPIVOTDATA("Order ID",$L$3,"Region","West","Inventory Status","Low Stock")/GETPIVOTDATA("Order ID",$L$3,"Region","West") -> 0.094339623 | N14: =GETPIVOTDATA("Order ID",$L$3,"Region","West","Inventory Status","Overstock")/GETPIVOTDATA("Order ID",$L$3,"Region","West") -> 0.36657682
A15: Low Stock | B15: 4178555.4 | F15: DirectWholesale | G15: 43 | H15: 232 | I15: 275 | L15: East | M15: =GETPIVOTDATA("Order ID",$L$3,"Region","East","Inventory Status","Low Stock")/GETPIVOTDATA("Order ID",$L$3,"Region","East") -> 0.071232877 | N15: =GETPIVOTDATA("Order ID",$L$3,"Region","East","Inventory Status","Overstock")/GETPIVOTDATA("Order ID",$L$3,"Region","East") -> 0.44657534
A16: Overstock | B16: 1.6303796e+08 | F16: Bedsheet Set | H16: 11 | I16: 11
A17: Grand Total | B17: 2.8928574e+08 | F17: Bluetooth Speaker | G17: 2 | H17: 9 | I17: 11 | L17: Row Labels | M17: Sum of Stockout Days | N17: Average of Stockout Days | O17: Count of Order ID
F18: Coffee Maker | G18: 1 | H18: 16 | I18: 17 | L18: East | M18: 251 | N18: 0.68767123 | O18: 365
A19: Overstock Inventory Value % | B19: =GETPIVOTDATA("Inventory Value",$A$13,"Inventory Status","Overstock")/GETPIVOTDATA("Inventory Value",$A$13) -> 0.56358794 | F19: Cricket Bat | G19: 1 | H19: 10 | I19: 11 | L19: North | M19: 328 | N19: 0.84102564 | O19: 390
F20: Desk Lamp | G20: 3 | H20: 12 | I20: 15 | L20: South | M20: 363 | N20: 0.97058824 | O20: 374
A21: Inventory Status | B21: Overstock | F21: Face Wash | G21: 3 | H21: 13 | I21: 16 | L21: West | M21: 306 | N21: 0.82479784 | O21: 371
F22: Football | G22: 1 | H22: 12 | I22: 13 | L22: Grand Total | M22: 1248 | N22: 0.832 | O22: 1500
A23: Row Labels | B23: Sum of Inventory Value | C23: Sum of Closing Stock | F23: Hoodie | G23: 3 | H23: 13 | I23: 16
A24: Coffee Maker | B24: 24860657 | C24: 7707 | F24: Jeans | G24: 3 | H24: 11 | I24: 14
A25: Running Shoes | B25: 18461006 | C25: 6745 | F25: Keyboard | G25: 2 | H25: 7 | I25: 9 | L25: Sum of Inventory Value | M25: Column Labels
A26: Sneakers | B26: 13839151 | C26: 5738 | F26: Moisturizer | G26: 2 | H26: 9 | I26: 11 | L26: Row Labels | M26: Healthy | N26: Low Stock | O26: Overstock | P26: Grand Total
A27: Cricket Bat | B27: 10052262 | C27: 4597 | F27: Running Shoes | H27: 14 | I27: 14 | L27: East | M27: 29924269 | N27: 729352.61 | O27: 48066939 | P27: 78720561
A28: Jeans | B28: 9533097.5 | C28: 5943 | F28: Shampoo | G28: 2 | H28: 17 | I28: 19 | L28: North | M28: 30128827 | N28: 1513096.8 | O28: 41674321 | P28: 73316245
A29: Bluetooth Speaker | B29: 8811293.8 | C29: 4989 | F29: Sneakers | G29: 4 | H29: 13 | I29: 17 | L29: South | M29: 30040347 | N29: 722773.07 | O29: 42207557 | P29: 72970676
A30: Bedsheet Set | B30: 7791975.2 | C30: 5162 | F30: Storage Box | G30: 2 | H30: 5 | I30: 7 | L30: West | M30: 31975788 | N30: 1213333 | O30: 31089140 | P30: 64278262
A31: Desk Lamp | B31: 7760927.7 | C31: 6965 | F31: Sunscreen | G31: 4 | H31: 12 | I31: 16 | L31: Grand Total | M31: 1.2206923e+08 | N31: 4178555.4 | O31: 1.6303796e+08 | P31: 2.8928574e+08
A32: Football | B32: 7268247.1 | C32: 5529 | F32: T-Shirt | G32: 5 | H32: 17 | I32: 22
A33: USB-C Hub | B33: 6705179.8 | C33: 5558 | F33: USB-C Hub | G33: 2 | H33: 7 | I33: 9 | L33: Row Labels | M33: Count of Order ID
A34: Hoodie | B34: 6315870.2 | C34: 4834 | F34: Wireless Mouse | G34: 3 | H34: 17 | I34: 20 | L34: Cancelled | M34: 178
A35: Storage Box | B35: 5754653.1 | C35: 7121 | F35: Yoga Mat | H35: 7 | I35: 7 | L35: Delivered | M35: 1008
A36: Sunscreen | B36: 5304948.4 | C36: 8160 | F36: GlobalMart | G36: 64 | H36: 269 | I36: 333 | L36: Pending | M36: 192
A37: Yoga Mat | B37: 5177807.6 | C37: 5138 | F37: Bedsheet Set | G37: 3 | H37: 10 | I37: 13 | L37: Returned | M37: 122
A38: Keyboard | B38: 5089560.8 | C38: 3600 | F38: Bluetooth Speaker | G38: 5 | H38: 12 | I38: 17 | L38: Grand Total | M38: 1500
A39: Wireless Mouse | B39: 4770464 | C39: 5383 | F39: Coffee Maker | G39: 8 | H39: 8 | I39: 16
A40: Shampoo | B40: 4680707.6 | C40: 9225 | F40: Cricket Bat | G40: 3 | H40: 17 | I40: 20 | L40: Cancellation Rate | M40: =GETPIVOTDATA("Order ID",$L$33,"Order Status","Cancelled")/GETPIVOTDATA("Order ID",$L$33) -> 0.11866667
A41: T-Shirt | B41: 4364116.1 | C41: 6230 | F41: Desk Lamp | H41: 15 | I41: 15 | L41: Pending Rate | M41: =GETPIVOTDATA("Order ID",$L$33,"Order Status","Pending")/GETPIVOTDATA("Order ID",$L$33) -> 0.128
A42: Moisturizer | B42: 3478640.9 | C42: 5857 | F42: Face Wash | G42: 6 | H42: 16 | I42: 22 | L42: Return Rate | M42: =GETPIVOTDATA("Order ID",$L$33,"Order Status","Returned")/GETPIVOTDATA("Order ID",$L$33) -> 0.081333333
...

Sheet Dashboard
A1: PRODUCT INVENTORY ANALYSIS
A2: TOTAL ORDERS | B2: FULFILLMENT RATE | C2: CANCELLATION RATE | D2: PENDING ORDERS | E2: TOTAL INVENTORY VALUE | F2: OVERSTOCK INVENTORY VALUE
A3: =GETPIVOTDATA("Count of Order ID",Analysis!$A$3) -> 1500 | B3: =Analysis!M43 -> 0.672 | C3: =Analysis!M40 -> 0.11866667 | D3: =GETPIVOTDATA("Order ID",Analysis!$L$33,"Order Status","Pending") -> 192 | E3: =GETPIVOTDATA("Inventory Value",Analysis!$L$25) -> 2.8928574e+08 | F3: =GETPIVOTDATA("Inventory Value",Analysis!$L$25,"Inventory Status","Overstock") -> 1.6303796e+08
A84: KEY OPERATIONAL INSIGHTS
A86: 1. Overstock Capital
A87: ₹16.30 Cr of inventory value is tied up in overstock, representing 56.36% of total inventory value.
A89: 2. Stockout Risk
A90: Low Stock inventory averages 4.94 stockout days and accounts for 50.6% of total stockout days.
A92: 3. Supplier Alert
A93: TechSource has an 83.33% late-delivery rate for Bluetooth Speakers (10 of 12 deliveries were late).
A95: 4. Regional Alert
A96: South has the lowest fulfillment rate at 64.44% and the highest average stockout days at 0.97.
A98: 5. Order Performance
A99: Overall fulfillment is 67.20%, while 12.80% of orders remain pending and 11.87% are cancelled.
A101: 6. Product Risk
A102: Storage Box has the highest cancellation rate at 24.29%, while Sneakers have the highest pending rate at 20.48%.
